Traceback (most recent call last):
  File "c:\users\52377\appdata\local\programs\python\python38\lib\site-packages\jupyter_core\utils\__init__.py", line 154, in wrapped
    asyncio.get_running_loop()
RuntimeError: no running event loop

During handling of the above exception, another exception occurred:

Traceback (most recent call last):
  File "c:\users\52377\appdata\local\programs\python\python38\lib\site-packages\jupyter_cache\executors\utils.py", line 58, in single_nb_execution
    executenb(
  File "c:\users\52377\appdata\local\programs\python\python38\lib\site-packages\nbclient\client.py", line 1305, in execute
    return NotebookClient(nb=nb, resources=resources, km=km, **kwargs).execute()
  File "c:\users\52377\appdata\local\programs\python\python38\lib\site-packages\jupyter_core\utils\__init__.py", line 158, in wrapped
    return loop.run_until_complete(inner)
  File "c:\users\52377\appdata\local\programs\python\python38\lib\asyncio\base_events.py", line 616, in run_until_complete
    return future.result()
  File "c:\users\52377\appdata\local\programs\python\python38\lib\site-packages\nbclient\client.py", line 705, in async_execute
    await self.async_execute_cell(
  File "c:\users\52377\appdata\local\programs\python\python38\lib\site-packages\nbclient\client.py", line 1058, in async_execute_cell
    await self._check_raise_for_error(cell, cell_index, exec_reply)
  File "c:\users\52377\appdata\local\programs\python\python38\lib\site-packages\nbclient\client.py", line 914, in _check_raise_for_error
    raise CellExecutionError.from_cell_and_msg(cell, exec_reply_content)
nbclient.exceptions.CellExecutionError: An error occurred while executing the following cell:
------------------
# Log target
df_reg_mp = df_reg_mp.copy()
y_log = np.log10(df_reg_mp["Solubility_mol_per_L"] + 1e-6)

# Features and split
X = df_reg_mp[["MolWt","LogP","TPSA","NumRings"]].values
X_tr, X_te, y_tr, y_te = train_test_split(X, y_log, test_size=0.2, random_state=15)

# Plots
plt.figure(figsize=(5,3))
plt.hist(y_log, bins=30, alpha=0.85)
plt.xlabel("log10(Solubility + 1e-6)"); plt.ylabel("Count"); plt.title("Log-solubility")
plt.show()

pd.plotting.scatter_matrix(df_reg_mp[["MolWt","LogP","TPSA","NumRings"]], figsize=(5.5,5.5))
plt.suptitle("Descriptor scatter matrix", y=1.02); plt.show()
------------------


[1;31m---------------------------------------------------------------------------[0m
[1;31mNameError[0m                                 Traceback (most recent call last)
Cell [1;32mIn[1], line 2[0m
[0;32m      1[0m [38;5;66;03m# Log target[39;00m
[1;32m----> 2[0m df_reg_mp [38;5;241m=[39m [43mdf_reg_mp[49m[38;5;241m.[39mcopy()
[0;32m      3[0m y_log [38;5;241m=[39m np[38;5;241m.[39mlog10(df_reg_mp[[38;5;124m"[39m[38;5;124mSolubility_mol_per_L[39m[38;5;124m"[39m] [38;5;241m+[39m [38;5;241m1e-6[39m)
[0;32m      5[0m [38;5;66;03m# Features and split[39;00m

[1;31mNameError[0m: name 'df_reg_mp' is not defined

