Traceback (most recent call last):
  File "c:\users\52377\appdata\local\programs\python\python38\lib\site-packages\jupyter_core\utils\__init__.py", line 154, in wrapped
    asyncio.get_running_loop()
RuntimeError: no running event loop

During handling of the above exception, another exception occurred:

Traceback (most recent call last):
  File "c:\users\52377\appdata\local\programs\python\python38\lib\site-packages\jupyter_cache\executors\utils.py", line 58, in single_nb_execution
    executenb(
  File "c:\users\52377\appdata\local\programs\python\python38\lib\site-packages\nbclient\client.py", line 1305, in execute
    return NotebookClient(nb=nb, resources=resources, km=km, **kwargs).execute()
  File "c:\users\52377\appdata\local\programs\python\python38\lib\site-packages\jupyter_core\utils\__init__.py", line 158, in wrapped
    return loop.run_until_complete(inner)
  File "c:\users\52377\appdata\local\programs\python\python38\lib\asyncio\base_events.py", line 616, in run_until_complete
    return future.result()
  File "c:\users\52377\appdata\local\programs\python\python38\lib\site-packages\nbclient\client.py", line 705, in async_execute
    await self.async_execute_cell(
  File "c:\users\52377\appdata\local\programs\python\python38\lib\site-packages\nbclient\client.py", line 1058, in async_execute_cell
    await self._check_raise_for_error(cell, cell_index, exec_reply)
  File "c:\users\52377\appdata\local\programs\python\python38\lib\site-packages\nbclient\client.py", line 914, in _check_raise_for_error
    raise CellExecutionError.from_cell_and_msg(cell, exec_reply_content)
nbclient.exceptions.CellExecutionError: An error occurred while executing the following cell:
------------------
rng = np.random.default_rng(17)

pos_idx = np.where(y_lab_noisy == 1)[0]
reveal = rng.random(len(pos_idx)) < 0.30
P_idx = pos_idx[reveal]

X_P = X_lab[P_idx]
mask_lab_rest = np.ones(len(X_lab), dtype=bool)
mask_lab_rest[P_idx] = False
X_U = np.vstack([X_lab[mask_lab_rest], X_unlab])

print("P shape:", X_P.shape, " U shape:", X_U.shape)
------------------


[1;31m---------------------------------------------------------------------------[0m
[1;31mNameError[0m                                 Traceback (most recent call last)
Cell [1;32mIn[1], line 1[0m
[1;32m----> 1[0m rng [38;5;241m=[39m [43mnp[49m[38;5;241m.[39mrandom[38;5;241m.[39mdefault_rng([38;5;241m17[39m)
[0;32m      3[0m pos_idx [38;5;241m=[39m np[38;5;241m.[39mwhere(y_lab_noisy [38;5;241m==[39m [38;5;241m1[39m)[[38;5;241m0[39m]
[0;32m      4[0m reveal [38;5;241m=[39m rng[38;5;241m.[39mrandom([38;5;28mlen[39m(pos_idx)) [38;5;241m<[39m [38;5;241m0.30[39m

[1;31mNameError[0m: name 'np' is not defined

