Traceback (most recent call last):
  File "C:\Users\52377\AppData\Local\Programs\Python\Python313\Lib\site-packages\jupyter_core\utils\__init__.py", line 154, in wrapped
    asyncio.get_running_loop()
    ~~~~~~~~~~~~~~~~~~~~~~~~^^
RuntimeError: no running event loop

During handling of the above exception, another exception occurred:

Traceback (most recent call last):
  File "C:\Users\52377\AppData\Local\Programs\Python\Python313\Lib\site-packages\jupyter_cache\executors\utils.py", line 58, in single_nb_execution
    executenb(
    ~~~~~~~~~^
        nb,
        ^^^
    ...<4 lines>...
        **kwargs,
        ^^^^^^^^^
    )
    ^
  File "C:\Users\52377\AppData\Local\Programs\Python\Python313\Lib\site-packages\nbclient\client.py", line 1319, in execute
    return NotebookClient(nb=nb, resources=resources, km=km, **kwargs).execute()
           ~~~~~~~~~~~~~~~~~~~~~~~~~~~~~~~~~~~~~~~~~~~~~~~~~~~~~~~~~~~~~~~~~~~^^
  File "C:\Users\52377\AppData\Local\Programs\Python\Python313\Lib\site-packages\jupyter_core\utils\__init__.py", line 158, in wrapped
    return loop.run_until_complete(inner)
           ~~~~~~~~~~~~~~~~~~~~~~~^^^^^^^
  File "C:\Users\52377\AppData\Local\Programs\Python\Python313\Lib\asyncio\base_events.py", line 725, in run_until_complete
    return future.result()
           ~~~~~~~~~~~~~^^
  File "C:\Users\52377\AppData\Local\Programs\Python\Python313\Lib\site-packages\nbclient\client.py", line 709, in async_execute
    await self.async_execute_cell(
        cell, index, execution_count=self.code_cells_executed + 1
    )
  File "C:\Users\52377\AppData\Local\Programs\Python\Python313\Lib\site-packages\nbclient\client.py", line 1062, in async_execute_cell
    await self._check_raise_for_error(cell, cell_index, exec_reply)
  File "C:\Users\52377\AppData\Local\Programs\Python\Python313\Lib\site-packages\nbclient\client.py", line 918, in _check_raise_for_error
    raise CellExecutionError.from_cell_and_msg(cell, exec_reply_content)
nbclient.exceptions.CellExecutionError: An error occurred while executing the following cell:
------------------
tree_stump = DecisionTreeRegressor(max_depth=1, random_state=0)
tree_stump.fit(X_tr, y_tr)

print("Train R2:", r2_score(y_tr, tree_stump.predict(X_tr)).round(3))
print("Test  R2:", r2_score(y_te, tree_stump.predict(X_te)).round(3))
print("Feature importances:", dict(zip(feat, tree_stump.feature_importances_.round(3))))
------------------


[31m---------------------------------------------------------------------------[39m
[31mAttributeError[39m                            Traceback (most recent call last)
[36mCell[39m[36m [39m[32mIn[7][39m[32m, line 4[39m
[32m      1[39m tree_stump = DecisionTreeRegressor(max_depth=[32m1[39m, random_state=[32m0[39m)
[32m      2[39m tree_stump.fit(X_tr, y_tr)
[32m----> [39m[32m4[39m [38;5;28mprint[39m([33m"[39m[33mTrain R2:[39m[33m"[39m, [43mr2_score[49m[43m([49m[43my_tr[49m[43m,[49m[43m [49m[43mtree_stump[49m[43m.[49m[43mpredict[49m[43m([49m[43mX_tr[49m[43m)[49m[43m)[49m[43m.[49m[43mround[49m([32m3[39m))
[32m      5[39m [38;5;28mprint[39m([33m"[39m[33mTest  R2:[39m[33m"[39m, r2_score(y_te, tree_stump.predict(X_te)).round([32m3[39m))
[32m      6[39m [38;5;28mprint[39m([33m"[39m[33mFeature importances:[39m[33m"[39m, [38;5;28mdict[39m([38;5;28mzip[39m(feat, tree_stump.feature_importances_.round([32m3[39m))))

[31mAttributeError[39m: 'float' object has no attribute 'round'

