Traceback (most recent call last):
  File "C:\Users\52377\AppData\Local\Programs\Python\Python313\Lib\site-packages\jupyter_core\utils\__init__.py", line 154, in wrapped
    asyncio.get_running_loop()
    ~~~~~~~~~~~~~~~~~~~~~~~~^^
RuntimeError: no running event loop

During handling of the above exception, another exception occurred:

Traceback (most recent call last):
  File "C:\Users\52377\AppData\Local\Programs\Python\Python313\Lib\site-packages\jupyter_cache\executors\utils.py", line 58, in single_nb_execution
    executenb(
    ~~~~~~~~~^
        nb,
        ^^^
    ...<4 lines>...
        **kwargs,
        ^^^^^^^^^
    )
    ^
  File "C:\Users\52377\AppData\Local\Programs\Python\Python313\Lib\site-packages\nbclient\client.py", line 1319, in execute
    return NotebookClient(nb=nb, resources=resources, km=km, **kwargs).execute()
           ~~~~~~~~~~~~~~~~~~~~~~~~~~~~~~~~~~~~~~~~~~~~~~~~~~~~~~~~~~~~~~~~~~~^^
  File "C:\Users\52377\AppData\Local\Programs\Python\Python313\Lib\site-packages\jupyter_core\utils\__init__.py", line 158, in wrapped
    return loop.run_until_complete(inner)
           ~~~~~~~~~~~~~~~~~~~~~~~^^^^^^^
  File "C:\Users\52377\AppData\Local\Programs\Python\Python313\Lib\asyncio\base_events.py", line 725, in run_until_complete
    return future.result()
           ~~~~~~~~~~~~~^^
  File "C:\Users\52377\AppData\Local\Programs\Python\Python313\Lib\site-packages\nbclient\client.py", line 709, in async_execute
    await self.async_execute_cell(
        cell, index, execution_count=self.code_cells_executed + 1
    )
  File "C:\Users\52377\AppData\Local\Programs\Python\Python313\Lib\site-packages\nbclient\client.py", line 1062, in async_execute_cell
    await self._check_raise_for_error(cell, cell_index, exec_reply)
  File "C:\Users\52377\AppData\Local\Programs\Python\Python313\Lib\site-packages\nbclient\client.py", line 918, in _check_raise_for_error
    raise CellExecutionError.from_cell_and_msg(cell, exec_reply_content)
nbclient.exceptions.CellExecutionError: An error occurred while executing the following cell:
------------------
import seaborn as sns
import matplotlib.pyplot as plt

vars = ["MolWt","LogP","TPSA","NumRings",
        "NumHAcceptors","NumHDonors","NumRotatableBonds",
        "HeavyAtomCount","FractionCSP3","NumAromaticRings"]

fig, axes = plt.subplots(len(vars), 1, figsize=(6, 20), sharex=False)

for i, v in enumerate(vars):
    sns.scatterplot(
        data=df10,
        x="MolWt", y=v,   # fix one descriptor on x-axis (e.g., MolWt)
        ax=axes[i], s=20, alpha=0.7
    )
    axes[i].set_ylabel(v)

plt.tight_layout()
plt.show()
------------------


[31m---------------------------------------------------------------------------[39m
[31mModuleNotFoundError[39m                       Traceback (most recent call last)
[36mCell[39m[36m [39m[32mIn[10][39m[32m, line 1[39m
[32m----> [39m[32m1[39m [38;5;28;01mimport[39;00m[38;5;250m [39m[34;01mseaborn[39;00m[38;5;250m [39m[38;5;28;01mas[39;00m[38;5;250m [39m[34;01msns[39;00m
[32m      2[39m [38;5;28;01mimport[39;00m[38;5;250m [39m[34;01mmatplotlib[39;00m[34;01m.[39;00m[34;01mpyplot[39;00m[38;5;250m [39m[38;5;28;01mas[39;00m[38;5;250m [39m[34;01mplt[39;00m
[32m      4[39m [38;5;28mvars[39m = [[33m"[39m[33mMolWt[39m[33m"[39m,[33m"[39m[33mLogP[39m[33m"[39m,[33m"[39m[33mTPSA[39m[33m"[39m,[33m"[39m[33mNumRings[39m[33m"[39m,
[32m      5[39m         [33m"[39m[33mNumHAcceptors[39m[33m"[39m,[33m"[39m[33mNumHDonors[39m[33m"[39m,[33m"[39m[33mNumRotatableBonds[39m[33m"[39m,
[32m      6[39m         [33m"[39m[33mHeavyAtomCount[39m[33m"[39m,[33m"[39m[33mFractionCSP3[39m[33m"[39m,[33m"[39m[33mNumAromaticRings[39m[33m"[39m]

[31mModuleNotFoundError[39m: No module named 'seaborn'

