Traceback (most recent call last):
  File "C:\Users\52377\AppData\Local\Programs\Python\Python313\Lib\site-packages\jupyter_core\utils\__init__.py", line 154, in wrapped
    asyncio.get_running_loop()
    ~~~~~~~~~~~~~~~~~~~~~~~~^^
RuntimeError: no running event loop

During handling of the above exception, another exception occurred:

Traceback (most recent call last):
  File "C:\Users\52377\AppData\Local\Programs\Python\Python313\Lib\site-packages\jupyter_cache\executors\utils.py", line 58, in single_nb_execution
    executenb(
    ~~~~~~~~~^
        nb,
        ^^^
    ...<4 lines>...
        **kwargs,
        ^^^^^^^^^
    )
    ^
  File "C:\Users\52377\AppData\Local\Programs\Python\Python313\Lib\site-packages\nbclient\client.py", line 1319, in execute
    return NotebookClient(nb=nb, resources=resources, km=km, **kwargs).execute()
           ~~~~~~~~~~~~~~~~~~~~~~~~~~~~~~~~~~~~~~~~~~~~~~~~~~~~~~~~~~~~~~~~~~~^^
  File "C:\Users\52377\AppData\Local\Programs\Python\Python313\Lib\site-packages\jupyter_core\utils\__init__.py", line 158, in wrapped
    return loop.run_until_complete(inner)
           ~~~~~~~~~~~~~~~~~~~~~~~^^^^^^^
  File "C:\Users\52377\AppData\Local\Programs\Python\Python313\Lib\asyncio\base_events.py", line 725, in run_until_complete
    return future.result()
           ~~~~~~~~~~~~~^^
  File "C:\Users\52377\AppData\Local\Programs\Python\Python313\Lib\site-packages\nbclient\client.py", line 709, in async_execute
    await self.async_execute_cell(
        cell, index, execution_count=self.code_cells_executed + 1
    )
  File "C:\Users\52377\AppData\Local\Programs\Python\Python313\Lib\site-packages\nbclient\client.py", line 1062, in async_execute_cell
    await self._check_raise_for_error(cell, cell_index, exec_reply)
  File "C:\Users\52377\AppData\Local\Programs\Python\Python313\Lib\site-packages\nbclient\client.py", line 918, in _check_raise_for_error
    raise CellExecutionError.from_cell_and_msg(cell, exec_reply_content)
nbclient.exceptions.CellExecutionError: An error occurred while executing the following cell:
------------------
df_reg = df[["MolWt","LogP","TPSA","NumRings","Melting Point"]].dropna()
X = df_reg[["MolWt","LogP","TPSA","NumRings"]].values
y = df_reg["Melting Point"].values
Xtr, Xte, ytr, yte = train_test_split(X, y, test_size=0.2, random_state=7)

pipe = Pipeline([
    ("scaler", StandardScaler()),
    ("mlp", MLPRegressor(hidden_layer_sizes=(32,), activation="relu",
                         alpha=1e-3, learning_rate_init=0.01,
                         max_iter=1500, random_state=0))
]).fit(Xtr, ytr)

yhat = pipe.predict(Xte)
print(f"MSE={mean_squared_error(yte,yhat):.2f}  MAE={mean_absolute_error(yte,yhat):.2f}  R2={r2_score(yte,yhat):.3f}")

plt.figure(figsize=(4.5,4))
plt.scatter(yte, yhat, alpha=0.65)
lims = [min(yte.min(), yhat.min()), max(yte.max(), yhat.max())]
plt.plot(lims, lims, "k--")
plt.xlabel("True MP"); plt.ylabel("Pred MP"); plt.title("Q1 parity")
plt.show()
------------------


[31m---------------------------------------------------------------------------[39m
[31mNameError[39m                                 Traceback (most recent call last)
[36mCell[39m[36m [39m[32mIn[1][39m[32m, line 1[39m
[32m----> [39m[32m1[39m df_reg = [43mdf[49m[[[33m"[39m[33mMolWt[39m[33m"[39m,[33m"[39m[33mLogP[39m[33m"[39m,[33m"[39m[33mTPSA[39m[33m"[39m,[33m"[39m[33mNumRings[39m[33m"[39m,[33m"[39m[33mMelting Point[39m[33m"[39m]].dropna()
[32m      2[39m X = df_reg[[[33m"[39m[33mMolWt[39m[33m"[39m,[33m"[39m[33mLogP[39m[33m"[39m,[33m"[39m[33mTPSA[39m[33m"[39m,[33m"[39m[33mNumRings[39m[33m"[39m]].values
[32m      3[39m y = df_reg[[33m"[39m[33mMelting Point[39m[33m"[39m].values

[31mNameError[39m: name 'df' is not defined

