Traceback (most recent call last):
  File "C:\Users\52377\AppData\Local\Programs\Python\Python313\Lib\site-packages\jupyter_core\utils\__init__.py", line 154, in wrapped
    asyncio.get_running_loop()
    ~~~~~~~~~~~~~~~~~~~~~~~~^^
RuntimeError: no running event loop

During handling of the above exception, another exception occurred:

Traceback (most recent call last):
  File "C:\Users\52377\AppData\Local\Programs\Python\Python313\Lib\site-packages\jupyter_cache\executors\utils.py", line 58, in single_nb_execution
    executenb(
    ~~~~~~~~~^
        nb,
        ^^^
    ...<4 lines>...
        **kwargs,
        ^^^^^^^^^
    )
    ^
  File "C:\Users\52377\AppData\Local\Programs\Python\Python313\Lib\site-packages\nbclient\client.py", line 1319, in execute
    return NotebookClient(nb=nb, resources=resources, km=km, **kwargs).execute()
           ~~~~~~~~~~~~~~~~~~~~~~~~~~~~~~~~~~~~~~~~~~~~~~~~~~~~~~~~~~~~~~~~~~~^^
  File "C:\Users\52377\AppData\Local\Programs\Python\Python313\Lib\site-packages\jupyter_core\utils\__init__.py", line 158, in wrapped
    return loop.run_until_complete(inner)
           ~~~~~~~~~~~~~~~~~~~~~~~^^^^^^^
  File "C:\Users\52377\AppData\Local\Programs\Python\Python313\Lib\asyncio\base_events.py", line 725, in run_until_complete
    return future.result()
           ~~~~~~~~~~~~~^^
  File "C:\Users\52377\AppData\Local\Programs\Python\Python313\Lib\site-packages\nbclient\client.py", line 709, in async_execute
    await self.async_execute_cell(
        cell, index, execution_count=self.code_cells_executed + 1
    )
  File "C:\Users\52377\AppData\Local\Programs\Python\Python313\Lib\site-packages\nbclient\client.py", line 1062, in async_execute_cell
    await self._check_raise_for_error(cell, cell_index, exec_reply)
  File "C:\Users\52377\AppData\Local\Programs\Python\Python313\Lib\site-packages\nbclient\client.py", line 918, in _check_raise_for_error
    raise CellExecutionError.from_cell_and_msg(cell, exec_reply_content)
nbclient.exceptions.CellExecutionError: An error occurred while executing the following cell:
------------------
acc_lr = accuracy_score(y_test, LogisticRegression(max_iter=500, random_state=0).fit(X_train,y_train).predict(X_test))
acc_svc = accuracy_score(y_test, SVC(probability=True, random_state=0).fit(X_train,y_train).predict(X_test))
acc_rf  = accuracy_score(y_test, RandomForestClassifier(n_estimators=100, random_state=0, n_jobs=-1).fit(X_train,y_train).predict(X_test))

pd.DataFrame({
    "Model": ["LogReg", "SVC", "RandomForest", "Voting-Hard", "Voting-Soft"],
    "Accuracy": [acc_lr, acc_svc, acc_rf, accuracy_score(y_test, vote_clf_hard.predict(X_test)), accuracy_score(y_test, vote_clf_soft.predict(X_test))]
})
------------------


[31m---------------------------------------------------------------------------[39m
[31mNameError[39m                                 Traceback (most recent call last)
[36mCell[39m[36m [39m[32mIn[37][39m[32m, line 2[39m
[32m      1[39m acc_lr = accuracy_score(y_test, LogisticRegression(max_iter=[32m500[39m, random_state=[32m0[39m).fit(X_train,y_train).predict(X_test))
[32m----> [39m[32m2[39m acc_svc = accuracy_score(y_test, [43mSVC[49m(probability=[38;5;28;01mTrue[39;00m, random_state=[32m0[39m).fit(X_train,y_train).predict(X_test))
[32m      3[39m acc_rf  = accuracy_score(y_test, RandomForestClassifier(n_estimators=[32m100[39m, random_state=[32m0[39m, n_jobs=-[32m1[39m).fit(X_train,y_train).predict(X_test))
[32m      5[39m pd.DataFrame({
[32m      6[39m     [33m"[39m[33mModel[39m[33m"[39m: [[33m"[39m[33mLogReg[39m[33m"[39m, [33m"[39m[33mSVC[39m[33m"[39m, [33m"[39m[33mRandomForest[39m[33m"[39m, [33m"[39m[33mVoting-Hard[39m[33m"[39m, [33m"[39m[33mVoting-Soft[39m[33m"[39m],
[32m      7[39m     [33m"[39m[33mAccuracy[39m[33m"[39m: [acc_lr, acc_svc, acc_rf, accuracy_score(y_test, vote_clf_hard.predict(X_test)), accuracy_score(y_test, vote_clf_soft.predict(X_test))]
[32m      8[39m })

[31mNameError[39m: name 'SVC' is not defined

