Traceback (most recent call last):
  File "C:\Users\52377\AppData\Local\Programs\Python\Python313\Lib\site-packages\jupyter_core\utils\__init__.py", line 154, in wrapped
    asyncio.get_running_loop()
    ~~~~~~~~~~~~~~~~~~~~~~~~^^
RuntimeError: no running event loop

During handling of the above exception, another exception occurred:

Traceback (most recent call last):
  File "C:\Users\52377\AppData\Local\Programs\Python\Python313\Lib\site-packages\jupyter_cache\executors\utils.py", line 58, in single_nb_execution
    executenb(
    ~~~~~~~~~^
        nb,
        ^^^
    ...<4 lines>...
        **kwargs,
        ^^^^^^^^^
    )
    ^
  File "C:\Users\52377\AppData\Local\Programs\Python\Python313\Lib\site-packages\nbclient\client.py", line 1319, in execute
    return NotebookClient(nb=nb, resources=resources, km=km, **kwargs).execute()
           ~~~~~~~~~~~~~~~~~~~~~~~~~~~~~~~~~~~~~~~~~~~~~~~~~~~~~~~~~~~~~~~~~~~^^
  File "C:\Users\52377\AppData\Local\Programs\Python\Python313\Lib\site-packages\jupyter_core\utils\__init__.py", line 158, in wrapped
    return loop.run_until_complete(inner)
           ~~~~~~~~~~~~~~~~~~~~~~~^^^^^^^
  File "C:\Users\52377\AppData\Local\Programs\Python\Python313\Lib\asyncio\base_events.py", line 725, in run_until_complete
    return future.result()
           ~~~~~~~~~~~~~^^
  File "C:\Users\52377\AppData\Local\Programs\Python\Python313\Lib\site-packages\nbclient\client.py", line 709, in async_execute
    await self.async_execute_cell(
        cell, index, execution_count=self.code_cells_executed + 1
    )
  File "C:\Users\52377\AppData\Local\Programs\Python\Python313\Lib\site-packages\nbclient\client.py", line 1062, in async_execute_cell
    await self._check_raise_for_error(cell, cell_index, exec_reply)
  File "C:\Users\52377\AppData\Local\Programs\Python\Python313\Lib\site-packages\nbclient\client.py", line 918, in _check_raise_for_error
    raise CellExecutionError.from_cell_and_msg(cell, exec_reply_content)
nbclient.exceptions.CellExecutionError: An error occurred while executing the following cell:
------------------
from torch.utils.data import TensorDataset, DataLoader

dl_desc = DataLoader(
    TensorDataset(torch.from_numpy(Xz.astype(np.float32))),
    batch_size=64,
    shuffle=True,
)

# 3D latent AE and training loop (unpack with (xb,))
ae3 = TinyAE(in_dim=10, hid=64, z_dim=3)
opt = optim.Adam(ae3.parameters(), lr=1e-3)

for ep in range(4):
    for (xb,) in dl_desc:
        xr, z = ae3(xb)
        loss = nn.functional.mse_loss(xr, xb)
        opt.zero_grad(); loss.backward(); opt.step()

# Encode with the trained model
with torch.no_grad():
    Z3 = ae3.encode(torch.from_numpy(Xz.astype(np.float32))).numpy()


fig = plt.figure(figsize=(6, 5))
ax = fig.add_subplot(111, projection="3d")

p = ax.scatter(
    Z3[:, 0], Z3[:, 1], Z3[:, 2],
    c=df_small["LogP"].values,
    s=12, alpha=0.85
)
ax.set_xlabel("z0"); ax.set_ylabel("z1"); ax.set_zlabel("z2")
ax.set_title("AE latent space (3D), color = LogP")
cb = fig.colorbar(p, ax=ax, shrink=0.7, pad=0.1)
cb.set_label("LogP")
plt.show()


------------------


[31m---------------------------------------------------------------------------[39m
[31mNameError[39m                                 Traceback (most recent call last)
[36mCell[39m[36m [39m[32mIn[1][39m[32m, line 4[39m
[32m      1[39m [38;5;28;01mfrom[39;00m[38;5;250m [39m[34;01mtorch[39;00m[34;01m.[39;00m[34;01mutils[39;00m[34;01m.[39;00m[34;01mdata[39;00m[38;5;250m [39m[38;5;28;01mimport[39;00m TensorDataset, DataLoader
[32m      3[39m dl_desc = DataLoader(
[32m----> [39m[32m4[39m     TensorDataset([43mtorch[49m.from_numpy(Xz.astype(np.float32))),
[32m      5[39m     batch_size=[32m64[39m,
[32m      6[39m     shuffle=[38;5;28;01mTrue[39;00m,
[32m      7[39m )
[32m      9[39m [38;5;66;03m# 3D latent AE and training loop (unpack with (xb,))[39;00m
[32m     10[39m ae3 = TinyAE(in_dim=[32m10[39m, hid=[32m64[39m, z_dim=[32m3[39m)

[31mNameError[39m: name 'torch' is not defined

