Traceback (most recent call last):
  File "C:\Users\52377\AppData\Local\Programs\Python\Python313\Lib\site-packages\jupyter_core\utils\__init__.py", line 154, in wrapped
    asyncio.get_running_loop()
    ~~~~~~~~~~~~~~~~~~~~~~~~^^
RuntimeError: no running event loop

During handling of the above exception, another exception occurred:

Traceback (most recent call last):
  File "C:\Users\52377\AppData\Local\Programs\Python\Python313\Lib\site-packages\jupyter_cache\executors\utils.py", line 58, in single_nb_execution
    executenb(
    ~~~~~~~~~^
        nb,
        ^^^
    ...<4 lines>...
        **kwargs,
        ^^^^^^^^^
    )
    ^
  File "C:\Users\52377\AppData\Local\Programs\Python\Python313\Lib\site-packages\nbclient\client.py", line 1319, in execute
    return NotebookClient(nb=nb, resources=resources, km=km, **kwargs).execute()
           ~~~~~~~~~~~~~~~~~~~~~~~~~~~~~~~~~~~~~~~~~~~~~~~~~~~~~~~~~~~~~~~~~~~^^
  File "C:\Users\52377\AppData\Local\Programs\Python\Python313\Lib\site-packages\jupyter_core\utils\__init__.py", line 158, in wrapped
    return loop.run_until_complete(inner)
           ~~~~~~~~~~~~~~~~~~~~~~~^^^^^^^
  File "C:\Users\52377\AppData\Local\Programs\Python\Python313\Lib\asyncio\base_events.py", line 725, in run_until_complete
    return future.result()
           ~~~~~~~~~~~~~^^
  File "C:\Users\52377\AppData\Local\Programs\Python\Python313\Lib\site-packages\nbclient\client.py", line 709, in async_execute
    await self.async_execute_cell(
        cell, index, execution_count=self.code_cells_executed + 1
    )
  File "C:\Users\52377\AppData\Local\Programs\Python\Python313\Lib\site-packages\nbclient\client.py", line 1062, in async_execute_cell
    await self._check_raise_for_error(cell, cell_index, exec_reply)
  File "C:\Users\52377\AppData\Local\Programs\Python\Python313\Lib\site-packages\nbclient\client.py", line 918, in _check_raise_for_error
    raise CellExecutionError.from_cell_and_msg(cell, exec_reply_content)
nbclient.exceptions.CellExecutionError: An error occurred while executing the following cell:
------------------
# Q4 solution
df_reg = df[["SMILES","Melting Point"]].dropna().copy()
df_reg.to_csv("mp_data.csv", index=False)

!chemprop train \
  --data-path mp_data.csv \
  -t regression \
  -s SMILES \
  --target-columns "Melting Point" \
  -o mp_model_q4 \
  --num-replicates 1 \
  --epochs 20 \
  --metrics mae rmse r2 \
  --tracking-metric r2

pd.DataFrame({"SMILES": ["CCO","c1ccccc1","CC(=O)O","CCN(CC)CC","O=C(O)C(O)C"]}).to_csv("q4_smiles.csv", index=False)

!chemprop predict \
  --test-path q4_smiles.csv \
  --model-paths mp_model_q4/replicate_0/model_0/best.pt \
  --preds-path q4_preds.csv

pd.read_csv("q4_preds.csv")
------------------


[31m---------------------------------------------------------------------------[39m
[31mNameError[39m                                 Traceback (most recent call last)
[36mCell[39m[36m [39m[32mIn[1][39m[32m, line 2[39m
[32m      1[39m [38;5;66;03m# Q4 solution[39;00m
[32m----> [39m[32m2[39m df_reg = [43mdf[49m[[[33m"[39m[33mSMILES[39m[33m"[39m,[33m"[39m[33mMelting Point[39m[33m"[39m]].dropna().copy()
[32m      3[39m df_reg.to_csv([33m"[39m[33mmp_data.csv[39m[33m"[39m, index=[38;5;28;01mFalse[39;00m)
[32m      5[39m get_ipython().system([33m'[39m[33mchemprop train    --data-path mp_data.csv    -t regression    -s SMILES    --target-columns [39m[33m"[39m[33mMelting Point[39m[33m"[39m[33m    -o mp_model_q4    --num-replicates 1    --epochs 20    --metrics mae rmse r2    --tracking-metric r2[39m[33m'[39m)

[31mNameError[39m: name 'df' is not defined

