Traceback (most recent call last):
  File "C:\Users\52377\AppData\Local\Programs\Python\Python313\Lib\site-packages\jupyter_core\utils\__init__.py", line 154, in wrapped
    asyncio.get_running_loop()
    ~~~~~~~~~~~~~~~~~~~~~~~~^^
RuntimeError: no running event loop

During handling of the above exception, another exception occurred:

Traceback (most recent call last):
  File "C:\Users\52377\AppData\Local\Programs\Python\Python313\Lib\site-packages\jupyter_cache\executors\utils.py", line 58, in single_nb_execution
    executenb(
    ~~~~~~~~~^
        nb,
        ^^^
    ...<4 lines>...
        **kwargs,
        ^^^^^^^^^
    )
    ^
  File "C:\Users\52377\AppData\Local\Programs\Python\Python313\Lib\site-packages\nbclient\client.py", line 1319, in execute
    return NotebookClient(nb=nb, resources=resources, km=km, **kwargs).execute()
           ~~~~~~~~~~~~~~~~~~~~~~~~~~~~~~~~~~~~~~~~~~~~~~~~~~~~~~~~~~~~~~~~~~~^^
  File "C:\Users\52377\AppData\Local\Programs\Python\Python313\Lib\site-packages\jupyter_core\utils\__init__.py", line 158, in wrapped
    return loop.run_until_complete(inner)
           ~~~~~~~~~~~~~~~~~~~~~~~^^^^^^^
  File "C:\Users\52377\AppData\Local\Programs\Python\Python313\Lib\asyncio\base_events.py", line 725, in run_until_complete
    return future.result()
           ~~~~~~~~~~~~~^^
  File "C:\Users\52377\AppData\Local\Programs\Python\Python313\Lib\site-packages\nbclient\client.py", line 709, in async_execute
    await self.async_execute_cell(
        cell, index, execution_count=self.code_cells_executed + 1
    )
  File "C:\Users\52377\AppData\Local\Programs\Python\Python313\Lib\site-packages\nbclient\client.py", line 1062, in async_execute_cell
    await self._check_raise_for_error(cell, cell_index, exec_reply)
  File "C:\Users\52377\AppData\Local\Programs\Python\Python313\Lib\site-packages\nbclient\client.py", line 918, in _check_raise_for_error
    raise CellExecutionError.from_cell_and_msg(cell, exec_reply_content)
nbclient.exceptions.CellExecutionError: An error occurred while executing the following cell:
------------------
import plotly.express as px
from sklearn.preprocessing import StandardScaler
from sklearn.decomposition import PCA

# ---- prepare feature matrix ----
desc_cols = ["MolWt","LogP","TPSA","NumRings",
             "NumHAcceptors","NumHDonors","NumRotatableBonds",
             "HeavyAtomCount","FractionCSP3","NumAromaticRings"]

X_desc = df10[desc_cols].values

# ---- standardize and PCA ----
X_desc_std = StandardScaler().fit_transform(X_desc)
pca = PCA(n_components=2)
X_pca = pca.fit_transform(X_desc_std)

# ---- build dataframe with PCA scores ----
df_pca = df10.copy()
df_pca["PC1"] = X_pca[:,0]
df_pca["PC2"] = X_pca[:,1]

# ---- interactive scatter with custom size ----
fig = px.scatter(
    df_pca,
    x="PC1", y="PC2",
    color="NumRings",
    hover_data=["Compound Name"] + desc_cols,
    title="Interactive PCA of 10 Descriptors",
    width=1200, height=600   # <-- 12 wide, 6 tall
)
fig.show()
------------------


[31m---------------------------------------------------------------------------[39m
[31mModuleNotFoundError[39m                       Traceback (most recent call last)
[36mCell[39m[36m [39m[32mIn[16][39m[32m, line 1[39m
[32m----> [39m[32m1[39m [38;5;28;01mimport[39;00m[38;5;250m [39m[34;01mplotly[39;00m[34;01m.[39;00m[34;01mexpress[39;00m[38;5;250m [39m[38;5;28;01mas[39;00m[38;5;250m [39m[34;01mpx[39;00m
[32m      2[39m [38;5;28;01mfrom[39;00m[38;5;250m [39m[34;01msklearn[39;00m[34;01m.[39;00m[34;01mpreprocessing[39;00m[38;5;250m [39m[38;5;28;01mimport[39;00m StandardScaler
[32m      3[39m [38;5;28;01mfrom[39;00m[38;5;250m [39m[34;01msklearn[39;00m[34;01m.[39;00m[34;01mdecomposition[39;00m[38;5;250m [39m[38;5;28;01mimport[39;00m PCA

[31mModuleNotFoundError[39m: No module named 'plotly'

