Traceback (most recent call last):
  File "c:\users\52377\appdata\local\programs\python\python38\lib\site-packages\jupyter_core\utils\__init__.py", line 154, in wrapped
    asyncio.get_running_loop()
RuntimeError: no running event loop

During handling of the above exception, another exception occurred:

Traceback (most recent call last):
  File "c:\users\52377\appdata\local\programs\python\python38\lib\site-packages\jupyter_cache\executors\utils.py", line 58, in single_nb_execution
    executenb(
  File "c:\users\52377\appdata\local\programs\python\python38\lib\site-packages\nbclient\client.py", line 1305, in execute
    return NotebookClient(nb=nb, resources=resources, km=km, **kwargs).execute()
  File "c:\users\52377\appdata\local\programs\python\python38\lib\site-packages\jupyter_core\utils\__init__.py", line 158, in wrapped
    return loop.run_until_complete(inner)
  File "c:\users\52377\appdata\local\programs\python\python38\lib\asyncio\base_events.py", line 616, in run_until_complete
    return future.result()
  File "c:\users\52377\appdata\local\programs\python\python38\lib\site-packages\nbclient\client.py", line 705, in async_execute
    await self.async_execute_cell(
  File "c:\users\52377\appdata\local\programs\python\python38\lib\site-packages\nbclient\client.py", line 1058, in async_execute_cell
    await self._check_raise_for_error(cell, cell_index, exec_reply)
  File "c:\users\52377\appdata\local\programs\python\python38\lib\site-packages\nbclient\client.py", line 914, in _check_raise_for_error
    raise CellExecutionError.from_cell_and_msg(cell, exec_reply_content)
nbclient.exceptions.CellExecutionError: An error occurred while executing the following cell:
------------------
if Chem is not None:
    small = df_raw[["SMILES","Melting Point"]].dropna().sample(200, random_state=0)
    graphs, targets = [], []
    for smi, mp in zip(small["SMILES"], small["Melting Point"]):
        g = smiles_to_graph(smi)
        if g is not None:
            graphs.append(g); targets.append(mp)
    y_all = torch.tensor(targets, dtype=torch.float32).view(-1,1)
    len(graphs), y_all.shape
else:
    print("RDKit missing. Skip to Section 7.")
------------------


[1;31m---------------------------------------------------------------------------[0m
[1;31mNameError[0m                                 Traceback (most recent call last)
Cell [1;32mIn[22], line 2[0m
[0;32m      1[0m [38;5;28;01mif[39;00m Chem [38;5;129;01mis[39;00m [38;5;129;01mnot[39;00m [38;5;28;01mNone[39;00m:
[1;32m----> 2[0m     small [38;5;241m=[39m [43mdf_raw[49m[[[38;5;124m"[39m[38;5;124mSMILES[39m[38;5;124m"[39m,[38;5;124m"[39m[38;5;124mMelting Point[39m[38;5;124m"[39m]][38;5;241m.[39mdropna()[38;5;241m.[39msample([38;5;241m200[39m, random_state[38;5;241m=[39m[38;5;241m0[39m)
[0;32m      3[0m     graphs, targets [38;5;241m=[39m [], []
[0;32m      4[0m     [38;5;28;01mfor[39;00m smi, mp [38;5;129;01min[39;00m [38;5;28mzip[39m(small[[38;5;124m"[39m[38;5;124mSMILES[39m[38;5;124m"[39m], small[[38;5;124m"[39m[38;5;124mMelting Point[39m[38;5;124m"[39m]):

[1;31mNameError[0m: name 'df_raw' is not defined

