Traceback (most recent call last):
  File "c:\users\52377\appdata\local\programs\python\python38\lib\site-packages\jupyter_core\utils\__init__.py", line 154, in wrapped
    asyncio.get_running_loop()
RuntimeError: no running event loop

During handling of the above exception, another exception occurred:

Traceback (most recent call last):
  File "c:\users\52377\appdata\local\programs\python\python38\lib\site-packages\jupyter_cache\executors\utils.py", line 58, in single_nb_execution
    executenb(
  File "c:\users\52377\appdata\local\programs\python\python38\lib\site-packages\nbclient\client.py", line 1305, in execute
    return NotebookClient(nb=nb, resources=resources, km=km, **kwargs).execute()
  File "c:\users\52377\appdata\local\programs\python\python38\lib\site-packages\jupyter_core\utils\__init__.py", line 158, in wrapped
    return loop.run_until_complete(inner)
  File "c:\users\52377\appdata\local\programs\python\python38\lib\asyncio\base_events.py", line 616, in run_until_complete
    return future.result()
  File "c:\users\52377\appdata\local\programs\python\python38\lib\site-packages\nbclient\client.py", line 705, in async_execute
    await self.async_execute_cell(
  File "c:\users\52377\appdata\local\programs\python\python38\lib\site-packages\nbclient\client.py", line 1058, in async_execute_cell
    await self._check_raise_for_error(cell, cell_index, exec_reply)
  File "c:\users\52377\appdata\local\programs\python\python38\lib\site-packages\nbclient\client.py", line 914, in _check_raise_for_error
    raise CellExecutionError.from_cell_and_msg(cell, exec_reply_content)
nbclient.exceptions.CellExecutionError: An error occurred while executing the following cell:
------------------
rf_clf = RandomForestClassifier(
    n_estimators=300,
    max_depth=None,
    min_samples_leaf=3,
    max_features="sqrt",
    random_state=0,
    n_jobs=-1
)
rf_clf.fit(X_train, y_train)

print("OOB score:", rf_clf.oob_score_)
acc = accuracy_score(y_test, rf_clf.predict(X_test))
print("Test accuracy:", acc)
------------------


[1;31m---------------------------------------------------------------------------[0m
[1;31mAttributeError[0m                            Traceback (most recent call last)
Cell [1;32mIn[26], line 11[0m
[0;32m      1[0m rf_clf [38;5;241m=[39m RandomForestClassifier(
[0;32m      2[0m     n_estimators[38;5;241m=[39m[38;5;241m300[39m,
[0;32m      3[0m     max_depth[38;5;241m=[39m[38;5;28;01mNone[39;00m,
[1;32m   (...)[0m
[0;32m      7[0m     n_jobs[38;5;241m=[39m[38;5;241m-[39m[38;5;241m1[39m
[0;32m      8[0m )
[0;32m      9[0m rf_clf[38;5;241m.[39mfit(X_train, y_train)
[1;32m---> 11[0m [38;5;28mprint[39m([38;5;124m"[39m[38;5;124mOOB score:[39m[38;5;124m"[39m, [43mrf_clf[49m[38;5;241;43m.[39;49m[43moob_score_[49m)
[0;32m     12[0m acc [38;5;241m=[39m accuracy_score(y_test, rf_clf[38;5;241m.[39mpredict(X_test))
[0;32m     13[0m [38;5;28mprint[39m([38;5;124m"[39m[38;5;124mTest accuracy:[39m[38;5;124m"[39m, acc)

[1;31mAttributeError[0m: 'RandomForestClassifier' object has no attribute 'oob_score_'

