Traceback (most recent call last):
  File "c:\users\52377\appdata\local\programs\python\python38\lib\site-packages\jupyter_core\utils\__init__.py", line 154, in wrapped
    asyncio.get_running_loop()
RuntimeError: no running event loop

During handling of the above exception, another exception occurred:

Traceback (most recent call last):
  File "c:\users\52377\appdata\local\programs\python\python38\lib\site-packages\jupyter_cache\executors\utils.py", line 58, in single_nb_execution
    executenb(
  File "c:\users\52377\appdata\local\programs\python\python38\lib\site-packages\nbclient\client.py", line 1305, in execute
    return NotebookClient(nb=nb, resources=resources, km=km, **kwargs).execute()
  File "c:\users\52377\appdata\local\programs\python\python38\lib\site-packages\jupyter_core\utils\__init__.py", line 158, in wrapped
    return loop.run_until_complete(inner)
  File "c:\users\52377\appdata\local\programs\python\python38\lib\asyncio\base_events.py", line 616, in run_until_complete
    return future.result()
  File "c:\users\52377\appdata\local\programs\python\python38\lib\site-packages\nbclient\client.py", line 705, in async_execute
    await self.async_execute_cell(
  File "c:\users\52377\appdata\local\programs\python\python38\lib\site-packages\nbclient\client.py", line 1058, in async_execute_cell
    await self._check_raise_for_error(cell, cell_index, exec_reply)
  File "c:\users\52377\appdata\local\programs\python\python38\lib\site-packages\nbclient\client.py", line 914, in _check_raise_for_error
    raise CellExecutionError.from_cell_and_msg(cell, exec_reply_content)
nbclient.exceptions.CellExecutionError: An error occurred while executing the following cell:
------------------
import pandas as pd
from rdkit.Chem import Descriptors, Crippen, rdMolDescriptors

names = ["caffeine", "acetaminophen", "ibuprofen"]
rows = []
for nm in names:
    info = pubchem_smiles_by_name(nm)
    smi = info["smiles"]
    m = Chem.MolFromSmiles(smi)
    rows.append({
        "name": nm,
        "smiles": smi,
        "MolWt": Descriptors.MolWt(m),
        "LogP": Crippen.MolLogP(m),
        "HBD": rdMolDescriptors.CalcNumHBD(m),
        "HBA": rdMolDescriptors.CalcNumHBA(m),
        "TPSA": rdMolDescriptors.CalcTPSA(m)
    })

pd.DataFrame(rows)
------------------


[1;31m---------------------------------------------------------------------------[0m
[1;31mNameError[0m                                 Traceback (most recent call last)
Cell [1;32mIn[2], line 7[0m
[0;32m      5[0m rows [38;5;241m=[39m []
[0;32m      6[0m [38;5;28;01mfor[39;00m nm [38;5;129;01min[39;00m names:
[1;32m----> 7[0m     info [38;5;241m=[39m [43mpubchem_smiles_by_name[49m(nm)
[0;32m      8[0m     smi [38;5;241m=[39m info[[38;5;124m"[39m[38;5;124msmiles[39m[38;5;124m"[39m]
[0;32m      9[0m     m [38;5;241m=[39m Chem[38;5;241m.[39mMolFromSmiles(smi)

[1;31mNameError[0m: name 'pubchem_smiles_by_name' is not defined

