Traceback (most recent call last):
  File "c:\users\52377\appdata\local\programs\python\python38\lib\site-packages\jupyter_core\utils\__init__.py", line 154, in wrapped
    asyncio.get_running_loop()
RuntimeError: no running event loop

During handling of the above exception, another exception occurred:

Traceback (most recent call last):
  File "c:\users\52377\appdata\local\programs\python\python38\lib\site-packages\jupyter_cache\executors\utils.py", line 58, in single_nb_execution
    executenb(
  File "c:\users\52377\appdata\local\programs\python\python38\lib\site-packages\nbclient\client.py", line 1305, in execute
    return NotebookClient(nb=nb, resources=resources, km=km, **kwargs).execute()
  File "c:\users\52377\appdata\local\programs\python\python38\lib\site-packages\jupyter_core\utils\__init__.py", line 158, in wrapped
    return loop.run_until_complete(inner)
  File "c:\users\52377\appdata\local\programs\python\python38\lib\asyncio\base_events.py", line 616, in run_until_complete
    return future.result()
  File "c:\users\52377\appdata\local\programs\python\python38\lib\site-packages\nbclient\client.py", line 705, in async_execute
    await self.async_execute_cell(
  File "c:\users\52377\appdata\local\programs\python\python38\lib\site-packages\nbclient\client.py", line 1058, in async_execute_cell
    await self._check_raise_for_error(cell, cell_index, exec_reply)
  File "c:\users\52377\appdata\local\programs\python\python38\lib\site-packages\nbclient\client.py", line 914, in _check_raise_for_error
    raise CellExecutionError.from_cell_and_msg(cell, exec_reply_content)
nbclient.exceptions.CellExecutionError: An error occurred while executing the following cell:
------------------
mp  = nn.BondMessagePassing()        # node/edge update
agg = nn.MeanAggregation()           # pool node vectors
out = nn.RegressionFFN(              # simple FFN head
    output_transform=nn.UnscaleTransform.from_standard_scaler(scaler)
)
batch_norm = True
metrics = [nn.metrics.RMSE(), nn.metrics.MAE()]  # first metric used for early stopping
------------------


[1;31m---------------------------------------------------------------------------[0m
[1;31mNameError[0m                                 Traceback (most recent call last)
Cell [1;32mIn[5], line 1[0m
[1;32m----> 1[0m mp  [38;5;241m=[39m [43mnn[49m[38;5;241m.[39mBondMessagePassing()        [38;5;66;03m# node/edge update[39;00m
[0;32m      2[0m agg [38;5;241m=[39m nn[38;5;241m.[39mMeanAggregation()           [38;5;66;03m# pool node vectors[39;00m
[0;32m      3[0m out [38;5;241m=[39m nn[38;5;241m.[39mRegressionFFN(              [38;5;66;03m# simple FFN head[39;00m
[0;32m      4[0m     output_transform[38;5;241m=[39mnn[38;5;241m.[39mUnscaleTransform[38;5;241m.[39mfrom_standard_scaler(scaler)
[0;32m      5[0m )

[1;31mNameError[0m: name 'nn' is not defined

