Traceback (most recent call last):
  File "c:\users\52377\appdata\local\programs\python\python38\lib\site-packages\jupyter_core\utils\__init__.py", line 154, in wrapped
    asyncio.get_running_loop()
RuntimeError: no running event loop

During handling of the above exception, another exception occurred:

Traceback (most recent call last):
  File "c:\users\52377\appdata\local\programs\python\python38\lib\site-packages\jupyter_cache\executors\utils.py", line 58, in single_nb_execution
    executenb(
  File "c:\users\52377\appdata\local\programs\python\python38\lib\site-packages\nbclient\client.py", line 1305, in execute
    return NotebookClient(nb=nb, resources=resources, km=km, **kwargs).execute()
  File "c:\users\52377\appdata\local\programs\python\python38\lib\site-packages\jupyter_core\utils\__init__.py", line 158, in wrapped
    return loop.run_until_complete(inner)
  File "c:\users\52377\appdata\local\programs\python\python38\lib\asyncio\base_events.py", line 616, in run_until_complete
    return future.result()
  File "c:\users\52377\appdata\local\programs\python\python38\lib\site-packages\nbclient\client.py", line 705, in async_execute
    await self.async_execute_cell(
  File "c:\users\52377\appdata\local\programs\python\python38\lib\site-packages\nbclient\client.py", line 1058, in async_execute_cell
    await self._check_raise_for_error(cell, cell_index, exec_reply)
  File "c:\users\52377\appdata\local\programs\python\python38\lib\site-packages\nbclient\client.py", line 914, in _check_raise_for_error
    raise CellExecutionError.from_cell_and_msg(cell, exec_reply_content)
nbclient.exceptions.CellExecutionError: An error occurred while executing the following cell:
------------------
# Q1 solution
set_seed(0)
url = "https://raw.githubusercontent.com/zzhenglab/ai4chem/main/book/_data/C_H_oxidation_dataset.csv"
df_oxidation_raw = pd.read_csv(url)
def calc_descriptors(smiles):
    mol = Chem.MolFromSmiles(smiles)
    if mol is None:
        return pd.Series({
            "MolWt": None,
            "LogP": None,
            "TPSA": None,
            "NumRings": None
        })
    return pd.Series({
        "MolWt": Descriptors.MolWt(mol),                    # molecular weight
        "LogP": Crippen.MolLogP(mol),                       # octanol-water logP
        "TPSA": rdMolDescriptors.CalcTPSA(mol),             # topological polar surface area
        "NumRings": rdMolDescriptors.CalcNumRings(mol)      # number of rings
    })

# Apply the function to the SMILES column
desc_df = df_oxidation_raw["SMILES"].apply(calc_descriptors)

# Concatenate new descriptor columns to original DataFrame
df_clf = pd.concat([df_oxidation_raw, desc_df], axis=1)
df_reg = df_clf.copy() 

# Logistic regression baseline
from sklearn.linear_model import LogisticRegression
X = df_clf[["MolWt","LogP","TPSA","NumRings"]].values
y = df_clf["Toxicity"].str.lower().map({"toxic":1,"non_toxic":0}).values
Xtr,Xte,ytr,yte = train_test_split(X,y,test_size=0.2,random_state=42,stratify=y)
baseline = LogisticRegression(max_iter=1000).fit(Xtr,ytr)
print("Baseline acc:", accuracy_score(yte, baseline.predict(Xte)))

# MLP from scratch
class MLP_Q1(nn.Module):
    def __init__(self,in_dim,hidden=32,n_classes=2):
        super().__init__()
        self.fc1 = nn.Linear(in_dim,hidden)
        self.fc2 = nn.Linear(hidden,n_classes)
    def forward(self,x):
        return self.fc2(F.relu(self.fc1(x)))

model = MLP_Q1(4)
opt = torch.optim.Adam(model.parameters(), lr=1e-2)
loss_fn = nn.CrossEntropyLoss()

for epoch in range(200):
    xb = torch.tensor(Xtr, dtype=torch.float32)
    yb = torch.tensor(ytr, dtype=torch.long)
    opt.zero_grad()
    out = model(xb)
    loss = loss_fn(out,yb)
    loss.backward()
    opt.step()

model.eval()
ypred = model(torch.tensor(Xte, dtype=torch.float32)).argmax(1).numpy()
print("MLP acc:", accuracy_score(yte, ypred))
#For this question and the following questions, it is fine if the model performance is worse than the baseline. 
------------------


[1;31m---------------------------------------------------------------------------[0m
[1;31mNameError[0m                                 Traceback (most recent call last)
Cell [1;32mIn[1], line 2[0m
[0;32m      1[0m [38;5;66;03m# Q1 solution[39;00m
[1;32m----> 2[0m [43mset_seed[49m([38;5;241m0[39m)
[0;32m      3[0m url [38;5;241m=[39m [38;5;124m"[39m[38;5;124mhttps://raw.githubusercontent.com/zzhenglab/ai4chem/main/book/_data/C_H_oxidation_dataset.csv[39m[38;5;124m"[39m
[0;32m      4[0m df_oxidation_raw [38;5;241m=[39m pd[38;5;241m.[39mread_csv(url)

[1;31mNameError[0m: name 'set_seed' is not defined

