Traceback (most recent call last):
  File "C:\Users\52377\AppData\Local\Programs\Python\Python313\Lib\site-packages\jupyter_core\utils\__init__.py", line 154, in wrapped
    asyncio.get_running_loop()
    ~~~~~~~~~~~~~~~~~~~~~~~~^^
RuntimeError: no running event loop

During handling of the above exception, another exception occurred:

Traceback (most recent call last):
  File "C:\Users\52377\AppData\Local\Programs\Python\Python313\Lib\site-packages\jupyter_cache\executors\utils.py", line 58, in single_nb_execution
    executenb(
    ~~~~~~~~~^
        nb,
        ^^^
    ...<4 lines>...
        **kwargs,
        ^^^^^^^^^
    )
    ^
  File "C:\Users\52377\AppData\Local\Programs\Python\Python313\Lib\site-packages\nbclient\client.py", line 1319, in execute
    return NotebookClient(nb=nb, resources=resources, km=km, **kwargs).execute()
           ~~~~~~~~~~~~~~~~~~~~~~~~~~~~~~~~~~~~~~~~~~~~~~~~~~~~~~~~~~~~~~~~~~~^^
  File "C:\Users\52377\AppData\Local\Programs\Python\Python313\Lib\site-packages\jupyter_core\utils\__init__.py", line 158, in wrapped
    return loop.run_until_complete(inner)
           ~~~~~~~~~~~~~~~~~~~~~~~^^^^^^^
  File "C:\Users\52377\AppData\Local\Programs\Python\Python313\Lib\asyncio\base_events.py", line 725, in run_until_complete
    return future.result()
           ~~~~~~~~~~~~~^^
  File "C:\Users\52377\AppData\Local\Programs\Python\Python313\Lib\site-packages\nbclient\client.py", line 709, in async_execute
    await self.async_execute_cell(
        cell, index, execution_count=self.code_cells_executed + 1
    )
  File "C:\Users\52377\AppData\Local\Programs\Python\Python313\Lib\site-packages\nbclient\client.py", line 1062, in async_execute_cell
    await self._check_raise_for_error(cell, cell_index, exec_reply)
  File "C:\Users\52377\AppData\Local\Programs\Python\Python313\Lib\site-packages\nbclient\client.py", line 918, in _check_raise_for_error
    raise CellExecutionError.from_cell_and_msg(cell, exec_reply_content)
nbclient.exceptions.CellExecutionError: An error occurred while executing the following cell:
------------------
names = ["aspirin", "acetaminophen", "ibuprofen"]  # example list

for nm in names:
    info = pubchem_smiles(nm, isomeric=True)  # unified helper from Section 4.8
    cid = info["cid"]
    smi = info["smiles"]
    print(f"{nm}: CID={cid} SMILES={smi}")
    m = Chem.MolFromSmiles(smi)
    display(Draw.MolToImage(m, size=(260, 200)))
------------------


[31m---------------------------------------------------------------------------[39m
[31mNameError[39m                                 Traceback (most recent call last)
[36mCell[39m[36m [39m[32mIn[45][39m[32m, line 4[39m
[32m      1[39m names = [[33m"[39m[33maspirin[39m[33m"[39m, [33m"[39m[33macetaminophen[39m[33m"[39m, [33m"[39m[33mibuprofen[39m[33m"[39m]  [38;5;66;03m# example list[39;00m
[32m      3[39m [38;5;28;01mfor[39;00m nm [38;5;129;01min[39;00m names:
[32m----> [39m[32m4[39m     info = [43mpubchem_smiles[49m(nm, isomeric=[38;5;28;01mTrue[39;00m)  [38;5;66;03m# unified helper from Section 4.8[39;00m
[32m      5[39m     cid = info[[33m"[39m[33mcid[39m[33m"[39m]
[32m      6[39m     smi = info[[33m"[39m[33msmiles[39m[33m"[39m]

[31mNameError[39m: name 'pubchem_smiles' is not defined

