Traceback (most recent call last):
  File "c:\users\52377\appdata\local\programs\python\python38\lib\site-packages\jupyter_core\utils\__init__.py", line 154, in wrapped
    asyncio.get_running_loop()
RuntimeError: no running event loop

During handling of the above exception, another exception occurred:

Traceback (most recent call last):
  File "c:\users\52377\appdata\local\programs\python\python38\lib\site-packages\jupyter_cache\executors\utils.py", line 58, in single_nb_execution
    executenb(
  File "c:\users\52377\appdata\local\programs\python\python38\lib\site-packages\nbclient\client.py", line 1305, in execute
    return NotebookClient(nb=nb, resources=resources, km=km, **kwargs).execute()
  File "c:\users\52377\appdata\local\programs\python\python38\lib\site-packages\jupyter_core\utils\__init__.py", line 158, in wrapped
    return loop.run_until_complete(inner)
  File "c:\users\52377\appdata\local\programs\python\python38\lib\asyncio\base_events.py", line 616, in run_until_complete
    return future.result()
  File "c:\users\52377\appdata\local\programs\python\python38\lib\site-packages\nbclient\client.py", line 705, in async_execute
    await self.async_execute_cell(
  File "c:\users\52377\appdata\local\programs\python\python38\lib\site-packages\nbclient\client.py", line 1058, in async_execute_cell
    await self._check_raise_for_error(cell, cell_index, exec_reply)
  File "c:\users\52377\appdata\local\programs\python\python38\lib\site-packages\nbclient\client.py", line 914, in _check_raise_for_error
    raise CellExecutionError.from_cell_and_msg(cell, exec_reply_content)
nbclient.exceptions.CellExecutionError: An error occurred while executing the following cell:
------------------
acc_lr = accuracy_score(y_test, LogisticRegression(max_iter=500, random_state=0).fit(X_train,y_train).predict(X_test))
acc_svc = accuracy_score(y_test, SVC(probability=True, random_state=0).fit(X_train,y_train).predict(X_test))
acc_rf  = accuracy_score(y_test, RandomForestClassifier(n_estimators=100, random_state=0, n_jobs=-1).fit(X_train,y_train).predict(X_test))

pd.DataFrame({
    "Model": ["LogReg", "SVC", "RandomForest", "Voting-Hard", "Voting-Soft"],
    "Accuracy": [acc_lr, acc_svc, acc_rf, accuracy_score(y_test, vote_clf_hard.predict(X_test), accuracy_score(y_test, vote_clf_soft.predict(X_test))]
})
------------------


[1;36m  Cell [1;32mIn[36], line 7[1;36m[0m
[1;33m    "Accuracy": [acc_lr, acc_svc, acc_rf, accuracy_score(y_test, vote_clf_hard.predict(X_test), accuracy_score(y_test, vote_clf_soft.predict(X_test))][0m
[1;37m                                                                                                                                                     ^[0m
[1;31mSyntaxError[0m[1;31m:[0m closing parenthesis ']' does not match opening parenthesis '('


